  File "/home/laluna/Desktop/py395e/lib/python3.9/site-packages/botocore/client.py", line 535, in _api_call
    return self._make_api_call(operation_name, kwargs)
  File "/home/laluna/Desktop/py395e/lib/python3.9/site-packages/botocore/client.py", line 980, in _make_api_call
    raise error_class(parsed_response, operation_name)
botocore.exceptions.ClientError: An error occurred (InvalidSignatureException) when calling the Scan operation: Signature not yet current: 20230905T092922Z is still later than 20230905T092631Z (20230905T091131Z + 15 min.)
2023-09-05 17:29:42
Traceback (most recent call last):
  File "/home/laluna/summer2023/rosa_emic.py", line 160, in <module>
    checker.check_and_update()
  File "/home/laluna/summer2023/rosa_emic.py", line 61, in check_and_update
    response = self.table.scan(
  File "/home/laluna/Desktop/py395e/lib/python3.9/site-packages/boto3/resources/factory.py", line 580, in do_action
    response = action(self, *args, **kwargs)
  File "/home/laluna/Desktop/py395e/lib/python3.9/site-packages/boto3/resources/action.py", line 88, in __call__
    response = getattr(parent.meta.client, operation_name)(*args, **params)
  File "/home/laluna/Desktop/py395e/lib/python3.9/site-packages/botocore/client.py", line 535, in _api_call
    return self._make_api_call(operation_name, kwargs)
  File "/home/laluna/Desktop/py395e/lib/python3.9/site-packages/botocore/client.py", line 980, in _make_api_call
    raise error_class(parsed_response, operation_name)
botocore.exceptions.ClientError: An error occurred (InvalidSignatureException) when calling the Scan operation: Signature not yet current: 20230905T092942Z is still later than 20230905T092651Z (20230905T091151Z + 15 min.)
2023-09-05 17:30:03
Traceback (most recent call last):
  File "/home/laluna/summer2023/rosa_emic.py", line 160, in <module>
    checker.check_and_update()
  File "/home/laluna/summer2023/rosa_emic.py", line 61, in check_and_update
    response = self.table.scan(
  File "/home/laluna/Desktop/py395e/lib/python3.9/site-packages/boto3/resources/factory.py", line 580, in do_action
    response = action(self, *args, **kwargs)
  File "/home/laluna/Desktop/py395e/lib/python3.9/site-packages/boto3/resources/action.py", line 88, in __call__
    response = getattr(parent.meta.client, operation_name)(*args, **params)
  File "/home/laluna/Desktop/py395e/lib/python3.9/site-packages/botocore/client.py", line 535, in _api_call
    return self._make_api_call(operation_name, kwargs)
  File "/home/laluna/Desktop/py395e/lib/python3.9/site-packages/botocore/client.py", line 980, in _make_api_call
    raise error_class(parsed_response, operation_name)
botocore.exceptions.ClientError: An error occurred (InvalidSignatureException) when calling the Scan operation: Signature not yet current: 20230905T093003Z is still later than 20230905T092712Z (20230905T091212Z + 15 min.)
2023-09-05 17:30:23
Traceback (most recent call last):
  File "/home/laluna/summer2023/rosa_emic.py", line 160, in <module>
    checker.check_and_update()
  File "/home/laluna/summer2023/rosa_emic.py", line 61, in check_and_update
    response = self.table.scan(
  File "/home/laluna/Desktop/py395e/lib/python3.9/site-packages/boto3/resources/factory.py", line 580, in do_action
    response = action(self, *args, **kwargs)
  File "/home/laluna/Desktop/py395e/lib/python3.9/site-packages/boto3/resources/action.py", line 88, in __call__
    response = getattr(parent.meta.client, operation_name)(*args, **params)
  File "/home/laluna/Desktop/py395e/lib/python3.9/site-packages/botocore/client.py", line 535, in _api_call
    return self._make_api_call(operation_name, kwargs)
  File "/home/laluna/Desktop/py395e/lib/python3.9/site-packages/botocore/client.py", line 980, in _make_api_call
    raise error_class(parsed_response, operation_name)
botocore.exceptions.ClientError: An error occurred (InvalidSignatureException) when calling the Scan operation: Signature not yet current: 20230905T093023Z is still later than 20230905T092731Z (20230905T091231Z + 15 min.)
2023-09-05 17:30:43
Traceback (most recent call last):
  File "/home/laluna/summer2023/rosa_emic.py", line 160, in <module>
    checker.check_and_update()
  File "/home/laluna/summer2023/rosa_emic.py", line 61, in check_and_update
    response = self.table.scan(
  File "/home/laluna/Desktop/py395e/lib/python3.9/site-packages/boto3/resources/factory.py", line 580, in do_action
    response = action(self, *args, **kwargs)
  File "/home/laluna/Desktop/py395e/lib/python3.9/site-packages/boto3/resources/action.py", line 88, in __call__
    response = getattr(parent.meta.client, operation_name)(*args, **params)
  File "/home/laluna/Desktop/py395e/lib/python3.9/site-packages/botocore/client.py", line 535, in _api_call
    return self._make_api_call(operation_name, kwargs)
  File "/home/laluna/Desktop/py395e/lib/python3.9/site-packages/botocore/client.py", line 980, in _make_api_call
    raise error_class(parsed_response, operation_name)
botocore.exceptions.ClientError: An error occurred (InvalidSignatureException) when calling the Scan operation: Signature not yet current: 20230905T093043Z is still later than 20230905T092751Z (20230905T091251Z + 15 min.)
2023-09-05 17:31:02
Traceback (most recent call last):
  File "/home/laluna/summer2023/rosa_emic.py", line 160, in <module>
    checker.check_and_update()
  File "/home/laluna/summer2023/rosa_emic.py", line 61, in check_and_update
    response = self.table.scan(
  File "/home/laluna/Desktop/py395e/lib/python3.9/site-packages/boto3/resources/factory.py", line 580, in do_action
    response = action(self, *args, **kwargs)
  File "/home/laluna/Desktop/py395e/lib/python3.9/site-packages/boto3/resources/action.py", line 88, in __call__
    response = getattr(parent.meta.client, operation_name)(*args, **params)
  File "/home/laluna/Desktop/py395e/lib/python3.9/site-packages/botocore/client.py", line 535, in _api_call
    return self._make_api_call(operation_name, kwargs)
  File "/home/laluna/Desktop/py395e/lib/python3.9/site-packages/botocore/client.py", line 980, in _make_api_call
    raise error_class(parsed_response, operation_name)
botocore.exceptions.ClientError: An error occurred (InvalidSignatureException) when calling the Scan operation: Signature not yet current: 20230905T093102Z is still later than 20230905T092810Z (20230905T091310Z + 15 min.)
2023-09-05 17:31:22
Traceback (most recent call last):
  File "/home/laluna/summer2023/rosa_emic.py", line 160, in <module>
    checker.check_and_update()
  File "/home/laluna/summer2023/rosa_emic.py", line 61, in check_and_update
    response = self.table.scan(
  File "/home/laluna/Desktop/py395e/lib/python3.9/site-packages/boto3/resources/factory.py", line 580, in do_action
    response = action(self, *args, **kwargs)
  File "/home/laluna/Desktop/py395e/lib/python3.9/site-packages/boto3/resources/action.py", line 88, in __call__
    response = getattr(parent.meta.client, operation_name)(*args, **params)
  File "/home/laluna/Desktop/py395e/lib/python3.9/site-packages/botocore/client.py", line 535, in _api_call
    return self._make_api_call(operation_name, kwargs)
  File "/home/laluna/Desktop/py395e/lib/python3.9/site-packages/botocore/client.py", line 980, in _make_api_call
    raise error_class(parsed_response, operation_name)
botocore.exceptions.ClientError: An error occurred (InvalidSignatureException) when calling the Scan operation: Signature not yet current: 20230905T093122Z is still later than 20230905T092831Z (20230905T091331Z + 15 min.)
2023-09-05 17:31:42
Traceback (most recent call last):
  File "/home/laluna/summer2023/rosa_emic.py", line 160, in <module>
    checker.check_and_update()
  File "/home/laluna/summer2023/rosa_emic.py", line 61, in check_and_update
    response = self.table.scan(
  File "/home/laluna/Desktop/py395e/lib/python3.9/site-packages/boto3/resources/factory.py", line 580, in do_action
    response = action(self, *args, **kwargs)
  File "/home/laluna/Desktop/py395e/lib/python3.9/site-packages/boto3/resources/action.py", line 88, in __call__
    response = getattr(parent.meta.client, operation_name)(*args, **params)
  File "/home/laluna/Desktop/py395e/lib/python3.9/site-packages/botocore/client.py", line 535, in _api_call
    return self._make_api_call(operation_name, kwargs)
  File "/home/laluna/Desktop/py395e/lib/python3.9/site-packages/botocore/client.py", line 980, in _make_api_call
    raise error_class(parsed_response, operation_name)
botocore.exceptions.ClientError: An error occurred (InvalidSignatureException) when calling the Scan operation: Signature not yet current: 20230905T093142Z is still later than 20230905T092850Z (20230905T091350Z + 15 min.)
2023-09-05 17:32:02
Traceback (most recent call last):
  File "/home/laluna/summer2023/rosa_emic.py", line 160, in <module>
    checker.check_and_update()
  File "/home/laluna/summer2023/rosa_emic.py", line 61, in check_and_update
    response = self.table.scan(
  File "/home/laluna/Desktop/py395e/lib/python3.9/site-packages/boto3/resources/factory.py", line 580, in do_action
    response = action(self, *args, **kwargs)
  File "/home/laluna/Desktop/py395e/lib/python3.9/site-packages/boto3/resources/action.py", line 88, in __call__
    response = getattr(parent.meta.client, operation_name)(*args, **params)
  File "/home/laluna/Desktop/py395e/lib/python3.9/site-packages/botocore/client.py", line 535, in _api_call
    return self._make_api_call(operation_name, kwargs)
  File "/home/laluna/Desktop/py395e/lib/python3.9/site-packages/botocore/client.py", line 980, in _make_api_call
    raise error_class(parsed_response, operation_name)
botocore.exceptions.ClientError: An error occurred (InvalidSignatureException) when calling the Scan operation: Signature not yet current: 20230905T093202Z is still later than 20230905T092911Z (20230905T091411Z + 15 min.)
2023-09-05 17:32:22
Traceback (most recent call last):
  File "/home/laluna/summer2023/rosa_emic.py", line 160, in <module>
    checker.check_and_update()
  File "/home/laluna/summer2023/rosa_emic.py", line 61, in check_and_update
    response = self.table.scan(
  File "/home/laluna/Desktop/py395e/lib/python3.9/site-packages/boto3/resources/factory.py", line 580, in do_action
    response = action(self, *args, **kwargs)
  File "/home/laluna/Desktop/py395e/lib/python3.9/site-packages/boto3/resources/action.py", line 88, in __call__
    response = getattr(parent.meta.client, operation_name)(*args, **params)
  File "/home/laluna/Desktop/py395e/lib/python3.9/site-packages/botocore/client.py", line 535, in _api_call
    return self._make_api_call(operation_name, kwargs)
  File "/home/laluna/Desktop/py395e/lib/python3.9/site-packages/botocore/client.py", line 980, in _make_api_call
    raise error_class(parsed_response, operation_name)
botocore.exceptions.ClientError: An error occurred (InvalidSignatureException) when calling the Scan operation: Signature not yet current: 20230905T093222Z is still later than 20230905T092930Z (20230905T091430Z + 15 min.)
2023-09-05 17:32:42
Traceback (most recent call last):
  File "/home/laluna/summer2023/rosa_emic.py", line 160, in <module>
    checker.check_and_update()
  File "/home/laluna/summer2023/rosa_emic.py", line 61, in check_and_update
    response = self.table.scan(
  File "/home/laluna/Desktop/py395e/lib/python3.9/site-packages/boto3/resources/factory.py", line 580, in do_action
    response = action(self, *args, **kwargs)
  File "/home/laluna/Desktop/py395e/lib/python3.9/site-packages/boto3/resources/action.py", line 88, in __call__
    response = getattr(parent.meta.client, operation_name)(*args, **params)
  File "/home/laluna/Desktop/py395e/lib/python3.9/site-packages/botocore/client.py", line 535, in _api_call
    return self._make_api_call(operation_name, kwargs)
  File "/home/laluna/Desktop/py395e/lib/python3.9/site-packages/botocore/client.py", line 980, in _make_api_call
    raise error_class(parsed_response, operation_name)
botocore.exceptions.ClientError: An error occurred (InvalidSignatureException) when calling the Scan operation: Signature not yet current: 20230905T093242Z is still later than 20230905T092954Z (20230905T091454Z + 15 min.)
2023-09-05 17:33:02
Traceback (most recent call last):
  File "/home/laluna/summer2023/rosa_emic.py", line 160, in <module>
    checker.check_and_update()
  File "/home/laluna/summer2023/rosa_emic.py", line 61, in check_and_update
    response = self.table.scan(
  File "/home/laluna/Desktop/py395e/lib/python3.9/site-packages/boto3/resources/factory.py", line 580, in do_action
    response = action(self, *args, **kwargs)
  File "/home/laluna/Desktop/py395e/lib/python3.9/site-packages/boto3/resources/action.py", line 88, in __call__
    response = getattr(parent.meta.client, operation_name)(*args, **params)
  File "/home/laluna/Desktop/py395e/lib/python3.9/site-packages/botocore/client.py", line 535, in _api_call
    return self._make_api_call(operation_name, kwargs)
  File "/home/laluna/Desktop/py395e/lib/python3.9/site-packages/botocore/client.py", line 980, in _make_api_call
    raise error_class(parsed_response, operation_name)
botocore.exceptions.ClientError: An error occurred (InvalidSignatureException) when calling the Scan operation: Signature not yet current: 20230905T093405Z is still later than 20230905T093115Z (20230905T091615Z + 15 min.)
2023-09-05 17:33:22
Traceback (most recent call last):
  File "/home/laluna/summer2023/rosa_emic.py", line 160, in <module>
    checker.check_and_update()
  File "/home/laluna/summer2023/rosa_emic.py", line 61, in check_and_update
    response = self.table.scan(
  File "/home/laluna/Desktop/py395e/lib/python3.9/site-packages/boto3/resources/factory.py", line 580, in do_action
    response = action(self, *args, **kwargs)
  File "/home/laluna/Desktop/py395e/lib/python3.9/site-packages/boto3/resources/action.py", line 88, in __call__
    response = getattr(parent.meta.client, operation_name)(*args, **params)
  File "/home/laluna/Desktop/py395e/lib/python3.9/site-packages/botocore/client.py", line 535, in _api_call
    return self._make_api_call(operation_name, kwargs)
  File "/home/laluna/Desktop/py395e/lib/python3.9/site-packages/botocore/client.py", line 980, in _make_api_call
    raise error_class(parsed_response, operation_name)
botocore.exceptions.ClientError: An error occurred (InvalidSignatureException) when calling the Scan operation: Signature not yet current: 20230905T093422Z is still later than 20230905T093139Z (20230905T091639Z + 15 min.)
2023-09-05 17:34:02
Traceback (most recent call last):
  File "/home/laluna/summer2023/rosa_emic.py", line 160, in <module>
    checker.check_and_update()
  File "/home/laluna/summer2023/rosa_emic.py", line 61, in check_and_update
    response = self.table.scan(
  File "/home/laluna/Desktop/py395e/lib/python3.9/site-packages/boto3/resources/factory.py", line 580, in do_action
    response = action(self, *args, **kwargs)
  File "/home/laluna/Desktop/py395e/lib/python3.9/site-packages/boto3/resources/action.py", line 88, in __call__
    response = getattr(parent.meta.client, operation_name)(*args, **params)
  File "/home/laluna/Desktop/py395e/lib/python3.9/site-packages/botocore/client.py", line 535, in _api_call
    return self._make_api_call(operation_name, kwargs)
  File "/home/laluna/Desktop/py395e/lib/python3.9/site-packages/botocore/client.py", line 980, in _make_api_call
    raise error_class(parsed_response, operation_name)
botocore.exceptions.ClientError: An error occurred (InvalidSignatureException) when calling the Scan operation: Signature not yet current: 20230905T093402Z is still later than 20230905T093140Z (20230905T091640Z + 15 min.)
2023-09-05 17:33:42
Traceback (most recent call last):
  File "/home/laluna/summer2023/rosa_emic.py", line 160, in <module>
    checker.check_and_update()
  File "/home/laluna/summer2023/rosa_emic.py", line 61, in check_and_update
    response = self.table.scan(
  File "/home/laluna/Desktop/py395e/lib/python3.9/site-packages/boto3/resources/factory.py", line 580, in do_action
    response = action(self, *args, **kwargs)
  File "/home/laluna/Desktop/py395e/lib/python3.9/site-packages/boto3/resources/action.py", line 88, in __call__
    response = getattr(parent.meta.client, operation_name)(*args, **params)
  File "/home/laluna/Desktop/py395e/lib/python3.9/site-packages/botocore/client.py", line 535, in _api_call
    return self._make_api_call(operation_name, kwargs)
  File "/home/laluna/Desktop/py395e/lib/python3.9/site-packages/botocore/client.py", line 980, in _make_api_call
    raise error_class(parsed_response, operation_name)
botocore.exceptions.ClientError: An error occurred (InvalidSignatureException) when calling the Scan operation: Signature not yet current: 20230905T093442Z is still later than 20230905T093151Z (20230905T091651Z + 15 min.)
2023-09-05 17:34:42
Traceback (most recent call last):
  File "/home/laluna/summer2023/rosa_emic.py", line 160, in <module>
    checker.check_and_update()
  File "/home/laluna/summer2023/rosa_emic.py", line 61, in check_and_update
    response = self.table.scan(
  File "/home/laluna/Desktop/py395e/lib/python3.9/site-packages/boto3/resources/factory.py", line 580, in do_action
    response = action(self, *args, **kwargs)
  File "/home/laluna/Desktop/py395e/lib/python3.9/site-packages/boto3/resources/action.py", line 88, in __call__
    response = getattr(parent.meta.client, operation_name)(*args, **params)
  File "/home/laluna/Desktop/py395e/lib/python3.9/site-packages/botocore/client.py", line 535, in _api_call
    return self._make_api_call(operation_name, kwargs)
  File "/home/laluna/Desktop/py395e/lib/python3.9/site-packages/botocore/client.py", line 980, in _make_api_call
    raise error_class(parsed_response, operation_name)
botocore.exceptions.ClientError: An error occurred (InvalidSignatureException) when calling the Scan operation: Signature not yet current: 20230905T093442Z is still later than 20230905T093152Z (20230905T091652Z + 15 min.)
2023-09-05 17:34:22
Traceback (most recent call last):
  File "/home/laluna/summer2023/rosa_emic.py", line 160, in <module>
    checker.check_and_update()
  File "/home/laluna/summer2023/rosa_emic.py", line 61, in check_and_update
    response = self.table.scan(
  File "/home/laluna/Desktop/py395e/lib/python3.9/site-packages/boto3/resources/factory.py", line 580, in do_action
    response = action(self, *args, **kwargs)
  File "/home/laluna/Desktop/py395e/lib/python3.9/site-packages/boto3/resources/action.py", line 88, in __call__
    response = getattr(parent.meta.client, operation_name)(*args, **params)
  File "/home/laluna/Desktop/py395e/lib/python3.9/site-packages/botocore/client.py", line 535, in _api_call
    return self._make_api_call(operation_name, kwargs)
  File "/home/laluna/Desktop/py395e/lib/python3.9/site-packages/botocore/client.py", line 980, in _make_api_call
    raise error_class(parsed_response, operation_name)
botocore.exceptions.ClientError: An error occurred (InvalidSignatureException) when calling the Scan operation: Signature not yet current: 20230905T093422Z is still later than 20230905T093159Z (20230905T091659Z + 15 min.)
