  File "/home/laluna/Desktop/py395e/lib/python3.9/site-packages/botocore/client.py", line 535, in _api_call
    return self._make_api_call(operation_name, kwargs)
  File "/home/laluna/Desktop/py395e/lib/python3.9/site-packages/botocore/client.py", line 980, in _make_api_call
    raise error_class(parsed_response, operation_name)
botocore.exceptions.ClientError: An error occurred (InvalidSignatureException) when calling the Scan operation: Signature not yet current: 20231202T233002Z is still later than 20231202T232612Z (20231202T231112Z + 15 min.)
2023-12-03 07:30:22
Traceback (most recent call last):
  File "/home/laluna/summer2023/rosa_emic.py", line 160, in <module>
    checker.check_and_update()
  File "/home/laluna/summer2023/rosa_emic.py", line 61, in check_and_update
    response = self.table.scan(
  File "/home/laluna/Desktop/py395e/lib/python3.9/site-packages/boto3/resources/factory.py", line 580, in do_action
    response = action(self, *args, **kwargs)
  File "/home/laluna/Desktop/py395e/lib/python3.9/site-packages/boto3/resources/action.py", line 88, in __call__
    response = getattr(parent.meta.client, operation_name)(*args, **params)
  File "/home/laluna/Desktop/py395e/lib/python3.9/site-packages/botocore/client.py", line 535, in _api_call
    return self._make_api_call(operation_name, kwargs)
  File "/home/laluna/Desktop/py395e/lib/python3.9/site-packages/botocore/client.py", line 980, in _make_api_call
    raise error_class(parsed_response, operation_name)
botocore.exceptions.ClientError: An error occurred (InvalidSignatureException) when calling the Scan operation: Signature not yet current: 20231202T233022Z is still later than 20231202T232632Z (20231202T231132Z + 15 min.)
2023-12-03 07:30:42
Traceback (most recent call last):
  File "/home/laluna/summer2023/rosa_emic.py", line 160, in <module>
    checker.check_and_update()
  File "/home/laluna/summer2023/rosa_emic.py", line 61, in check_and_update
    response = self.table.scan(
  File "/home/laluna/Desktop/py395e/lib/python3.9/site-packages/boto3/resources/factory.py", line 580, in do_action
    response = action(self, *args, **kwargs)
  File "/home/laluna/Desktop/py395e/lib/python3.9/site-packages/boto3/resources/action.py", line 88, in __call__
    response = getattr(parent.meta.client, operation_name)(*args, **params)
  File "/home/laluna/Desktop/py395e/lib/python3.9/site-packages/botocore/client.py", line 535, in _api_call
    return self._make_api_call(operation_name, kwargs)
  File "/home/laluna/Desktop/py395e/lib/python3.9/site-packages/botocore/client.py", line 980, in _make_api_call
    raise error_class(parsed_response, operation_name)
botocore.exceptions.ClientError: An error occurred (InvalidSignatureException) when calling the Scan operation: Signature not yet current: 20231202T233042Z is still later than 20231202T232652Z (20231202T231152Z + 15 min.)
2023-12-03 07:31:02
Traceback (most recent call last):
  File "/home/laluna/summer2023/rosa_emic.py", line 160, in <module>
    checker.check_and_update()
  File "/home/laluna/summer2023/rosa_emic.py", line 61, in check_and_update
    response = self.table.scan(
  File "/home/laluna/Desktop/py395e/lib/python3.9/site-packages/boto3/resources/factory.py", line 580, in do_action
    response = action(self, *args, **kwargs)
  File "/home/laluna/Desktop/py395e/lib/python3.9/site-packages/boto3/resources/action.py", line 88, in __call__
    response = getattr(parent.meta.client, operation_name)(*args, **params)
  File "/home/laluna/Desktop/py395e/lib/python3.9/site-packages/botocore/client.py", line 535, in _api_call
    return self._make_api_call(operation_name, kwargs)
  File "/home/laluna/Desktop/py395e/lib/python3.9/site-packages/botocore/client.py", line 980, in _make_api_call
    raise error_class(parsed_response, operation_name)
botocore.exceptions.ClientError: An error occurred (InvalidSignatureException) when calling the Scan operation: Signature not yet current: 20231202T233102Z is still later than 20231202T232712Z (20231202T231212Z + 15 min.)
2023-12-03 07:31:22
Traceback (most recent call last):
  File "/home/laluna/summer2023/rosa_emic.py", line 160, in <module>
    checker.check_and_update()
  File "/home/laluna/summer2023/rosa_emic.py", line 61, in check_and_update
    response = self.table.scan(
  File "/home/laluna/Desktop/py395e/lib/python3.9/site-packages/boto3/resources/factory.py", line 580, in do_action
    response = action(self, *args, **kwargs)
  File "/home/laluna/Desktop/py395e/lib/python3.9/site-packages/boto3/resources/action.py", line 88, in __call__
    response = getattr(parent.meta.client, operation_name)(*args, **params)
  File "/home/laluna/Desktop/py395e/lib/python3.9/site-packages/botocore/client.py", line 535, in _api_call
    return self._make_api_call(operation_name, kwargs)
  File "/home/laluna/Desktop/py395e/lib/python3.9/site-packages/botocore/client.py", line 980, in _make_api_call
    raise error_class(parsed_response, operation_name)
botocore.exceptions.ClientError: An error occurred (InvalidSignatureException) when calling the Scan operation: Signature not yet current: 20231202T233122Z is still later than 20231202T232732Z (20231202T231232Z + 15 min.)
2023-12-03 07:31:42
Traceback (most recent call last):
  File "/home/laluna/summer2023/rosa_emic.py", line 160, in <module>
    checker.check_and_update()
  File "/home/laluna/summer2023/rosa_emic.py", line 61, in check_and_update
    response = self.table.scan(
  File "/home/laluna/Desktop/py395e/lib/python3.9/site-packages/boto3/resources/factory.py", line 580, in do_action
    response = action(self, *args, **kwargs)
  File "/home/laluna/Desktop/py395e/lib/python3.9/site-packages/boto3/resources/action.py", line 88, in __call__
    response = getattr(parent.meta.client, operation_name)(*args, **params)
  File "/home/laluna/Desktop/py395e/lib/python3.9/site-packages/botocore/client.py", line 535, in _api_call
    return self._make_api_call(operation_name, kwargs)
  File "/home/laluna/Desktop/py395e/lib/python3.9/site-packages/botocore/client.py", line 980, in _make_api_call
    raise error_class(parsed_response, operation_name)
botocore.exceptions.ClientError: An error occurred (InvalidSignatureException) when calling the Scan operation: Signature not yet current: 20231202T233142Z is still later than 20231202T232752Z (20231202T231252Z + 15 min.)
2023-12-03 07:32:02
Traceback (most recent call last):
  File "/home/laluna/summer2023/rosa_emic.py", line 160, in <module>
    checker.check_and_update()
  File "/home/laluna/summer2023/rosa_emic.py", line 61, in check_and_update
    response = self.table.scan(
  File "/home/laluna/Desktop/py395e/lib/python3.9/site-packages/boto3/resources/factory.py", line 580, in do_action
    response = action(self, *args, **kwargs)
  File "/home/laluna/Desktop/py395e/lib/python3.9/site-packages/boto3/resources/action.py", line 88, in __call__
    response = getattr(parent.meta.client, operation_name)(*args, **params)
  File "/home/laluna/Desktop/py395e/lib/python3.9/site-packages/botocore/client.py", line 535, in _api_call
    return self._make_api_call(operation_name, kwargs)
  File "/home/laluna/Desktop/py395e/lib/python3.9/site-packages/botocore/client.py", line 980, in _make_api_call
    raise error_class(parsed_response, operation_name)
botocore.exceptions.ClientError: An error occurred (InvalidSignatureException) when calling the Scan operation: Signature not yet current: 20231202T233202Z is still later than 20231202T232812Z (20231202T231312Z + 15 min.)
2023-12-03 07:32:22
Traceback (most recent call last):
  File "/home/laluna/summer2023/rosa_emic.py", line 160, in <module>
    checker.check_and_update()
  File "/home/laluna/summer2023/rosa_emic.py", line 61, in check_and_update
    response = self.table.scan(
  File "/home/laluna/Desktop/py395e/lib/python3.9/site-packages/boto3/resources/factory.py", line 580, in do_action
    response = action(self, *args, **kwargs)
  File "/home/laluna/Desktop/py395e/lib/python3.9/site-packages/boto3/resources/action.py", line 88, in __call__
    response = getattr(parent.meta.client, operation_name)(*args, **params)
  File "/home/laluna/Desktop/py395e/lib/python3.9/site-packages/botocore/client.py", line 535, in _api_call
    return self._make_api_call(operation_name, kwargs)
  File "/home/laluna/Desktop/py395e/lib/python3.9/site-packages/botocore/client.py", line 980, in _make_api_call
    raise error_class(parsed_response, operation_name)
botocore.exceptions.ClientError: An error occurred (InvalidSignatureException) when calling the Scan operation: Signature not yet current: 20231202T233222Z is still later than 20231202T232832Z (20231202T231332Z + 15 min.)
2023-12-03 07:32:42
Traceback (most recent call last):
  File "/home/laluna/summer2023/rosa_emic.py", line 160, in <module>
    checker.check_and_update()
  File "/home/laluna/summer2023/rosa_emic.py", line 61, in check_and_update
    response = self.table.scan(
  File "/home/laluna/Desktop/py395e/lib/python3.9/site-packages/boto3/resources/factory.py", line 580, in do_action
    response = action(self, *args, **kwargs)
  File "/home/laluna/Desktop/py395e/lib/python3.9/site-packages/boto3/resources/action.py", line 88, in __call__
    response = getattr(parent.meta.client, operation_name)(*args, **params)
  File "/home/laluna/Desktop/py395e/lib/python3.9/site-packages/botocore/client.py", line 535, in _api_call
    return self._make_api_call(operation_name, kwargs)
  File "/home/laluna/Desktop/py395e/lib/python3.9/site-packages/botocore/client.py", line 980, in _make_api_call
    raise error_class(parsed_response, operation_name)
botocore.exceptions.ClientError: An error occurred (InvalidSignatureException) when calling the Scan operation: Signature not yet current: 20231202T233242Z is still later than 20231202T232852Z (20231202T231352Z + 15 min.)
2023-12-03 07:33:02
Traceback (most recent call last):
  File "/home/laluna/summer2023/rosa_emic.py", line 160, in <module>
    checker.check_and_update()
  File "/home/laluna/summer2023/rosa_emic.py", line 61, in check_and_update
    response = self.table.scan(
  File "/home/laluna/Desktop/py395e/lib/python3.9/site-packages/boto3/resources/factory.py", line 580, in do_action
    response = action(self, *args, **kwargs)
  File "/home/laluna/Desktop/py395e/lib/python3.9/site-packages/boto3/resources/action.py", line 88, in __call__
    response = getattr(parent.meta.client, operation_name)(*args, **params)
  File "/home/laluna/Desktop/py395e/lib/python3.9/site-packages/botocore/client.py", line 535, in _api_call
    return self._make_api_call(operation_name, kwargs)
  File "/home/laluna/Desktop/py395e/lib/python3.9/site-packages/botocore/client.py", line 980, in _make_api_call
    raise error_class(parsed_response, operation_name)
botocore.exceptions.ClientError: An error occurred (InvalidSignatureException) when calling the Scan operation: Signature not yet current: 20231202T233302Z is still later than 20231202T232912Z (20231202T231412Z + 15 min.)
2023-12-03 07:33:22
Traceback (most recent call last):
  File "/home/laluna/summer2023/rosa_emic.py", line 160, in <module>
    checker.check_and_update()
  File "/home/laluna/summer2023/rosa_emic.py", line 61, in check_and_update
    response = self.table.scan(
  File "/home/laluna/Desktop/py395e/lib/python3.9/site-packages/boto3/resources/factory.py", line 580, in do_action
    response = action(self, *args, **kwargs)
  File "/home/laluna/Desktop/py395e/lib/python3.9/site-packages/boto3/resources/action.py", line 88, in __call__
    response = getattr(parent.meta.client, operation_name)(*args, **params)
  File "/home/laluna/Desktop/py395e/lib/python3.9/site-packages/botocore/client.py", line 535, in _api_call
    return self._make_api_call(operation_name, kwargs)
  File "/home/laluna/Desktop/py395e/lib/python3.9/site-packages/botocore/client.py", line 980, in _make_api_call
    raise error_class(parsed_response, operation_name)
botocore.exceptions.ClientError: An error occurred (InvalidSignatureException) when calling the Scan operation: Signature not yet current: 20231202T233322Z is still later than 20231202T232932Z (20231202T231432Z + 15 min.)
2023-12-03 07:33:42
Traceback (most recent call last):
  File "/home/laluna/summer2023/rosa_emic.py", line 160, in <module>
    checker.check_and_update()
  File "/home/laluna/summer2023/rosa_emic.py", line 61, in check_and_update
    response = self.table.scan(
  File "/home/laluna/Desktop/py395e/lib/python3.9/site-packages/boto3/resources/factory.py", line 580, in do_action
    response = action(self, *args, **kwargs)
  File "/home/laluna/Desktop/py395e/lib/python3.9/site-packages/boto3/resources/action.py", line 88, in __call__
    response = getattr(parent.meta.client, operation_name)(*args, **params)
  File "/home/laluna/Desktop/py395e/lib/python3.9/site-packages/botocore/client.py", line 535, in _api_call
    return self._make_api_call(operation_name, kwargs)
  File "/home/laluna/Desktop/py395e/lib/python3.9/site-packages/botocore/client.py", line 980, in _make_api_call
    raise error_class(parsed_response, operation_name)
botocore.exceptions.ClientError: An error occurred (InvalidSignatureException) when calling the Scan operation: Signature not yet current: 20231202T233342Z is still later than 20231202T232952Z (20231202T231452Z + 15 min.)
2023-12-03 07:34:02
Traceback (most recent call last):
  File "/home/laluna/summer2023/rosa_emic.py", line 160, in <module>
    checker.check_and_update()
  File "/home/laluna/summer2023/rosa_emic.py", line 61, in check_and_update
    response = self.table.scan(
  File "/home/laluna/Desktop/py395e/lib/python3.9/site-packages/boto3/resources/factory.py", line 580, in do_action
    response = action(self, *args, **kwargs)
  File "/home/laluna/Desktop/py395e/lib/python3.9/site-packages/boto3/resources/action.py", line 88, in __call__
    response = getattr(parent.meta.client, operation_name)(*args, **params)
  File "/home/laluna/Desktop/py395e/lib/python3.9/site-packages/botocore/client.py", line 535, in _api_call
    return self._make_api_call(operation_name, kwargs)
  File "/home/laluna/Desktop/py395e/lib/python3.9/site-packages/botocore/client.py", line 980, in _make_api_call
    raise error_class(parsed_response, operation_name)
botocore.exceptions.ClientError: An error occurred (InvalidSignatureException) when calling the Scan operation: Signature not yet current: 20231202T233403Z is still later than 20231202T233013Z (20231202T231513Z + 15 min.)
2023-12-03 07:34:22
Traceback (most recent call last):
  File "/home/laluna/summer2023/rosa_emic.py", line 160, in <module>
    checker.check_and_update()
  File "/home/laluna/summer2023/rosa_emic.py", line 61, in check_and_update
    response = self.table.scan(
  File "/home/laluna/Desktop/py395e/lib/python3.9/site-packages/boto3/resources/factory.py", line 580, in do_action
    response = action(self, *args, **kwargs)
  File "/home/laluna/Desktop/py395e/lib/python3.9/site-packages/boto3/resources/action.py", line 88, in __call__
    response = getattr(parent.meta.client, operation_name)(*args, **params)
  File "/home/laluna/Desktop/py395e/lib/python3.9/site-packages/botocore/client.py", line 535, in _api_call
    return self._make_api_call(operation_name, kwargs)
  File "/home/laluna/Desktop/py395e/lib/python3.9/site-packages/botocore/client.py", line 980, in _make_api_call
    raise error_class(parsed_response, operation_name)
botocore.exceptions.ClientError: An error occurred (InvalidSignatureException) when calling the Scan operation: Signature not yet current: 20231202T233422Z is still later than 20231202T233032Z (20231202T231532Z + 15 min.)
