  File "/home/laluna/Desktop/py395e/lib/python3.9/site-packages/botocore/client.py", line 535, in _api_call
    return self._make_api_call(operation_name, kwargs)
  File "/home/laluna/Desktop/py395e/lib/python3.9/site-packages/botocore/client.py", line 980, in _make_api_call
    raise error_class(parsed_response, operation_name)
botocore.exceptions.ClientError: An error occurred (InvalidSignatureException) when calling the Scan operation: Signature not yet current: 20230915T033502Z is still later than 20230915T033241Z (20230915T031741Z + 15 min.)
2023-09-15 11:35:22
Traceback (most recent call last):
  File "/home/laluna/summer2023/rosa_emic.py", line 160, in <module>
    checker.check_and_update()
  File "/home/laluna/summer2023/rosa_emic.py", line 61, in check_and_update
    response = self.table.scan(
  File "/home/laluna/Desktop/py395e/lib/python3.9/site-packages/boto3/resources/factory.py", line 580, in do_action
    response = action(self, *args, **kwargs)
  File "/home/laluna/Desktop/py395e/lib/python3.9/site-packages/boto3/resources/action.py", line 88, in __call__
    response = getattr(parent.meta.client, operation_name)(*args, **params)
  File "/home/laluna/Desktop/py395e/lib/python3.9/site-packages/botocore/client.py", line 535, in _api_call
    return self._make_api_call(operation_name, kwargs)
  File "/home/laluna/Desktop/py395e/lib/python3.9/site-packages/botocore/client.py", line 980, in _make_api_call
    raise error_class(parsed_response, operation_name)
botocore.exceptions.ClientError: An error occurred (InvalidSignatureException) when calling the Scan operation: Signature not yet current: 20230915T033522Z is still later than 20230915T033301Z (20230915T031801Z + 15 min.)
2023-09-15 11:35:42
Traceback (most recent call last):
  File "/home/laluna/summer2023/rosa_emic.py", line 160, in <module>
    checker.check_and_update()
  File "/home/laluna/summer2023/rosa_emic.py", line 61, in check_and_update
    response = self.table.scan(
  File "/home/laluna/Desktop/py395e/lib/python3.9/site-packages/boto3/resources/factory.py", line 580, in do_action
    response = action(self, *args, **kwargs)
  File "/home/laluna/Desktop/py395e/lib/python3.9/site-packages/boto3/resources/action.py", line 88, in __call__
    response = getattr(parent.meta.client, operation_name)(*args, **params)
  File "/home/laluna/Desktop/py395e/lib/python3.9/site-packages/botocore/client.py", line 535, in _api_call
    return self._make_api_call(operation_name, kwargs)
  File "/home/laluna/Desktop/py395e/lib/python3.9/site-packages/botocore/client.py", line 980, in _make_api_call
    raise error_class(parsed_response, operation_name)
botocore.exceptions.ClientError: An error occurred (InvalidSignatureException) when calling the Scan operation: Signature not yet current: 20230915T033542Z is still later than 20230915T033321Z (20230915T031821Z + 15 min.)
2023-09-15 11:36:02
Traceback (most recent call last):
  File "/home/laluna/summer2023/rosa_emic.py", line 160, in <module>
    checker.check_and_update()
  File "/home/laluna/summer2023/rosa_emic.py", line 61, in check_and_update
    response = self.table.scan(
  File "/home/laluna/Desktop/py395e/lib/python3.9/site-packages/boto3/resources/factory.py", line 580, in do_action
    response = action(self, *args, **kwargs)
  File "/home/laluna/Desktop/py395e/lib/python3.9/site-packages/boto3/resources/action.py", line 88, in __call__
    response = getattr(parent.meta.client, operation_name)(*args, **params)
  File "/home/laluna/Desktop/py395e/lib/python3.9/site-packages/botocore/client.py", line 535, in _api_call
    return self._make_api_call(operation_name, kwargs)
  File "/home/laluna/Desktop/py395e/lib/python3.9/site-packages/botocore/client.py", line 980, in _make_api_call
    raise error_class(parsed_response, operation_name)
botocore.exceptions.ClientError: An error occurred (InvalidSignatureException) when calling the Scan operation: Signature not yet current: 20230915T033602Z is still later than 20230915T033342Z (20230915T031842Z + 15 min.)
2023-09-15 11:36:22
Traceback (most recent call last):
  File "/home/laluna/summer2023/rosa_emic.py", line 160, in <module>
    checker.check_and_update()
  File "/home/laluna/summer2023/rosa_emic.py", line 61, in check_and_update
    response = self.table.scan(
  File "/home/laluna/Desktop/py395e/lib/python3.9/site-packages/boto3/resources/factory.py", line 580, in do_action
    response = action(self, *args, **kwargs)
  File "/home/laluna/Desktop/py395e/lib/python3.9/site-packages/boto3/resources/action.py", line 88, in __call__
    response = getattr(parent.meta.client, operation_name)(*args, **params)
  File "/home/laluna/Desktop/py395e/lib/python3.9/site-packages/botocore/client.py", line 535, in _api_call
    return self._make_api_call(operation_name, kwargs)
  File "/home/laluna/Desktop/py395e/lib/python3.9/site-packages/botocore/client.py", line 980, in _make_api_call
    raise error_class(parsed_response, operation_name)
botocore.exceptions.ClientError: An error occurred (InvalidSignatureException) when calling the Scan operation: Signature not yet current: 20230915T033622Z is still later than 20230915T033402Z (20230915T031902Z + 15 min.)
2023-09-15 11:36:42
Traceback (most recent call last):
  File "/home/laluna/summer2023/rosa_emic.py", line 160, in <module>
    checker.check_and_update()
  File "/home/laluna/summer2023/rosa_emic.py", line 61, in check_and_update
    response = self.table.scan(
  File "/home/laluna/Desktop/py395e/lib/python3.9/site-packages/boto3/resources/factory.py", line 580, in do_action
    response = action(self, *args, **kwargs)
  File "/home/laluna/Desktop/py395e/lib/python3.9/site-packages/boto3/resources/action.py", line 88, in __call__
    response = getattr(parent.meta.client, operation_name)(*args, **params)
  File "/home/laluna/Desktop/py395e/lib/python3.9/site-packages/botocore/client.py", line 535, in _api_call
    return self._make_api_call(operation_name, kwargs)
  File "/home/laluna/Desktop/py395e/lib/python3.9/site-packages/botocore/client.py", line 980, in _make_api_call
    raise error_class(parsed_response, operation_name)
botocore.exceptions.ClientError: An error occurred (InvalidSignatureException) when calling the Scan operation: Signature not yet current: 20230915T033642Z is still later than 20230915T033422Z (20230915T031922Z + 15 min.)
2023-09-15 11:37:02
Traceback (most recent call last):
  File "/home/laluna/summer2023/rosa_emic.py", line 160, in <module>
    checker.check_and_update()
  File "/home/laluna/summer2023/rosa_emic.py", line 61, in check_and_update
    response = self.table.scan(
  File "/home/laluna/Desktop/py395e/lib/python3.9/site-packages/boto3/resources/factory.py", line 580, in do_action
    response = action(self, *args, **kwargs)
  File "/home/laluna/Desktop/py395e/lib/python3.9/site-packages/boto3/resources/action.py", line 88, in __call__
    response = getattr(parent.meta.client, operation_name)(*args, **params)
  File "/home/laluna/Desktop/py395e/lib/python3.9/site-packages/botocore/client.py", line 535, in _api_call
    return self._make_api_call(operation_name, kwargs)
  File "/home/laluna/Desktop/py395e/lib/python3.9/site-packages/botocore/client.py", line 980, in _make_api_call
    raise error_class(parsed_response, operation_name)
botocore.exceptions.ClientError: An error occurred (InvalidSignatureException) when calling the Scan operation: Signature not yet current: 20230915T033702Z is still later than 20230915T033441Z (20230915T031941Z + 15 min.)
2023-09-15 11:37:22
Traceback (most recent call last):
  File "/home/laluna/summer2023/rosa_emic.py", line 160, in <module>
    checker.check_and_update()
  File "/home/laluna/summer2023/rosa_emic.py", line 61, in check_and_update
    response = self.table.scan(
  File "/home/laluna/Desktop/py395e/lib/python3.9/site-packages/boto3/resources/factory.py", line 580, in do_action
    response = action(self, *args, **kwargs)
  File "/home/laluna/Desktop/py395e/lib/python3.9/site-packages/boto3/resources/action.py", line 88, in __call__
    response = getattr(parent.meta.client, operation_name)(*args, **params)
  File "/home/laluna/Desktop/py395e/lib/python3.9/site-packages/botocore/client.py", line 535, in _api_call
    return self._make_api_call(operation_name, kwargs)
  File "/home/laluna/Desktop/py395e/lib/python3.9/site-packages/botocore/client.py", line 980, in _make_api_call
    raise error_class(parsed_response, operation_name)
botocore.exceptions.ClientError: An error occurred (InvalidSignatureException) when calling the Scan operation: Signature not yet current: 20230915T033722Z is still later than 20230915T033501Z (20230915T032001Z + 15 min.)
2023-09-15 11:37:42
Traceback (most recent call last):
  File "/home/laluna/summer2023/rosa_emic.py", line 160, in <module>
    checker.check_and_update()
  File "/home/laluna/summer2023/rosa_emic.py", line 61, in check_and_update
    response = self.table.scan(
  File "/home/laluna/Desktop/py395e/lib/python3.9/site-packages/boto3/resources/factory.py", line 580, in do_action
    response = action(self, *args, **kwargs)
  File "/home/laluna/Desktop/py395e/lib/python3.9/site-packages/boto3/resources/action.py", line 88, in __call__
    response = getattr(parent.meta.client, operation_name)(*args, **params)
  File "/home/laluna/Desktop/py395e/lib/python3.9/site-packages/botocore/client.py", line 535, in _api_call
    return self._make_api_call(operation_name, kwargs)
  File "/home/laluna/Desktop/py395e/lib/python3.9/site-packages/botocore/client.py", line 980, in _make_api_call
    raise error_class(parsed_response, operation_name)
botocore.exceptions.ClientError: An error occurred (InvalidSignatureException) when calling the Scan operation: Signature not yet current: 20230915T033742Z is still later than 20230915T033521Z (20230915T032021Z + 15 min.)
2023-09-15 11:38:02
Traceback (most recent call last):
  File "/home/laluna/summer2023/rosa_emic.py", line 160, in <module>
    checker.check_and_update()
  File "/home/laluna/summer2023/rosa_emic.py", line 61, in check_and_update
    response = self.table.scan(
  File "/home/laluna/Desktop/py395e/lib/python3.9/site-packages/boto3/resources/factory.py", line 580, in do_action
    response = action(self, *args, **kwargs)
  File "/home/laluna/Desktop/py395e/lib/python3.9/site-packages/boto3/resources/action.py", line 88, in __call__
    response = getattr(parent.meta.client, operation_name)(*args, **params)
  File "/home/laluna/Desktop/py395e/lib/python3.9/site-packages/botocore/client.py", line 535, in _api_call
    return self._make_api_call(operation_name, kwargs)
  File "/home/laluna/Desktop/py395e/lib/python3.9/site-packages/botocore/client.py", line 980, in _make_api_call
    raise error_class(parsed_response, operation_name)
botocore.exceptions.ClientError: An error occurred (InvalidSignatureException) when calling the Scan operation: Signature not yet current: 20230915T033802Z is still later than 20230915T033541Z (20230915T032041Z + 15 min.)
2023-09-15 11:38:22
Traceback (most recent call last):
  File "/home/laluna/summer2023/rosa_emic.py", line 160, in <module>
    checker.check_and_update()
  File "/home/laluna/summer2023/rosa_emic.py", line 61, in check_and_update
    response = self.table.scan(
  File "/home/laluna/Desktop/py395e/lib/python3.9/site-packages/boto3/resources/factory.py", line 580, in do_action
    response = action(self, *args, **kwargs)
  File "/home/laluna/Desktop/py395e/lib/python3.9/site-packages/boto3/resources/action.py", line 88, in __call__
    response = getattr(parent.meta.client, operation_name)(*args, **params)
  File "/home/laluna/Desktop/py395e/lib/python3.9/site-packages/botocore/client.py", line 535, in _api_call
    return self._make_api_call(operation_name, kwargs)
  File "/home/laluna/Desktop/py395e/lib/python3.9/site-packages/botocore/client.py", line 980, in _make_api_call
    raise error_class(parsed_response, operation_name)
botocore.exceptions.ClientError: An error occurred (InvalidSignatureException) when calling the Scan operation: Signature not yet current: 20230915T033822Z is still later than 20230915T033601Z (20230915T032101Z + 15 min.)
2023-09-15 11:38:42
Traceback (most recent call last):
  File "/home/laluna/summer2023/rosa_emic.py", line 160, in <module>
    checker.check_and_update()
  File "/home/laluna/summer2023/rosa_emic.py", line 61, in check_and_update
    response = self.table.scan(
  File "/home/laluna/Desktop/py395e/lib/python3.9/site-packages/boto3/resources/factory.py", line 580, in do_action
    response = action(self, *args, **kwargs)
  File "/home/laluna/Desktop/py395e/lib/python3.9/site-packages/boto3/resources/action.py", line 88, in __call__
    response = getattr(parent.meta.client, operation_name)(*args, **params)
  File "/home/laluna/Desktop/py395e/lib/python3.9/site-packages/botocore/client.py", line 535, in _api_call
    return self._make_api_call(operation_name, kwargs)
  File "/home/laluna/Desktop/py395e/lib/python3.9/site-packages/botocore/client.py", line 980, in _make_api_call
    raise error_class(parsed_response, operation_name)
botocore.exceptions.ClientError: An error occurred (InvalidSignatureException) when calling the Scan operation: Signature not yet current: 20230915T033842Z is still later than 20230915T033621Z (20230915T032121Z + 15 min.)
2023-09-15 11:39:02
Traceback (most recent call last):
  File "/home/laluna/summer2023/rosa_emic.py", line 160, in <module>
    checker.check_and_update()
  File "/home/laluna/summer2023/rosa_emic.py", line 61, in check_and_update
    response = self.table.scan(
  File "/home/laluna/Desktop/py395e/lib/python3.9/site-packages/boto3/resources/factory.py", line 580, in do_action
    response = action(self, *args, **kwargs)
  File "/home/laluna/Desktop/py395e/lib/python3.9/site-packages/boto3/resources/action.py", line 88, in __call__
    response = getattr(parent.meta.client, operation_name)(*args, **params)
  File "/home/laluna/Desktop/py395e/lib/python3.9/site-packages/botocore/client.py", line 535, in _api_call
    return self._make_api_call(operation_name, kwargs)
  File "/home/laluna/Desktop/py395e/lib/python3.9/site-packages/botocore/client.py", line 980, in _make_api_call
    raise error_class(parsed_response, operation_name)
botocore.exceptions.ClientError: An error occurred (InvalidSignatureException) when calling the Scan operation: Signature not yet current: 20230915T033902Z is still later than 20230915T033642Z (20230915T032142Z + 15 min.)
2023-09-15 11:39:22
Traceback (most recent call last):
  File "/home/laluna/summer2023/rosa_emic.py", line 160, in <module>
    checker.check_and_update()
  File "/home/laluna/summer2023/rosa_emic.py", line 61, in check_and_update
    response = self.table.scan(
  File "/home/laluna/Desktop/py395e/lib/python3.9/site-packages/boto3/resources/factory.py", line 580, in do_action
    response = action(self, *args, **kwargs)
  File "/home/laluna/Desktop/py395e/lib/python3.9/site-packages/boto3/resources/action.py", line 88, in __call__
    response = getattr(parent.meta.client, operation_name)(*args, **params)
  File "/home/laluna/Desktop/py395e/lib/python3.9/site-packages/botocore/client.py", line 535, in _api_call
    return self._make_api_call(operation_name, kwargs)
  File "/home/laluna/Desktop/py395e/lib/python3.9/site-packages/botocore/client.py", line 980, in _make_api_call
    raise error_class(parsed_response, operation_name)
botocore.exceptions.ClientError: An error occurred (InvalidSignatureException) when calling the Scan operation: Signature not yet current: 20230915T033922Z is still later than 20230915T033702Z (20230915T032202Z + 15 min.)
2023-09-15 11:39:42
Traceback (most recent call last):
  File "/home/laluna/summer2023/rosa_emic.py", line 160, in <module>
    checker.check_and_update()
  File "/home/laluna/summer2023/rosa_emic.py", line 61, in check_and_update
    response = self.table.scan(
  File "/home/laluna/Desktop/py395e/lib/python3.9/site-packages/boto3/resources/factory.py", line 580, in do_action
    response = action(self, *args, **kwargs)
  File "/home/laluna/Desktop/py395e/lib/python3.9/site-packages/boto3/resources/action.py", line 88, in __call__
    response = getattr(parent.meta.client, operation_name)(*args, **params)
  File "/home/laluna/Desktop/py395e/lib/python3.9/site-packages/botocore/client.py", line 535, in _api_call
    return self._make_api_call(operation_name, kwargs)
  File "/home/laluna/Desktop/py395e/lib/python3.9/site-packages/botocore/client.py", line 980, in _make_api_call
    raise error_class(parsed_response, operation_name)
botocore.exceptions.ClientError: An error occurred (InvalidSignatureException) when calling the Scan operation: Signature not yet current: 20230915T033942Z is still later than 20230915T033721Z (20230915T032221Z + 15 min.)
