  File "/home/laluna/Desktop/py395e/lib/python3.9/site-packages/botocore/client.py", line 535, in _api_call
    return self._make_api_call(operation_name, kwargs)
  File "/home/laluna/Desktop/py395e/lib/python3.9/site-packages/botocore/client.py", line 980, in _make_api_call
    raise error_class(parsed_response, operation_name)
botocore.exceptions.ClientError: An error occurred (UnrecognizedClientException) when calling the Scan operation: The security token included in the request is invalid.
2023-11-29 17:18:17
Traceback (most recent call last):
  File "/home/laluna/summer2023/rosa_emic.py", line 160, in <module>
    checker.check_and_update()
  File "/home/laluna/summer2023/rosa_emic.py", line 61, in check_and_update
    response = self.table.scan(
  File "/home/laluna/Desktop/py395e/lib/python3.9/site-packages/boto3/resources/factory.py", line 580, in do_action
    response = action(self, *args, **kwargs)
  File "/home/laluna/Desktop/py395e/lib/python3.9/site-packages/boto3/resources/action.py", line 88, in __call__
    response = getattr(parent.meta.client, operation_name)(*args, **params)
  File "/home/laluna/Desktop/py395e/lib/python3.9/site-packages/botocore/client.py", line 535, in _api_call
    return self._make_api_call(operation_name, kwargs)
  File "/home/laluna/Desktop/py395e/lib/python3.9/site-packages/botocore/client.py", line 980, in _make_api_call
    raise error_class(parsed_response, operation_name)
botocore.exceptions.ClientError: An error occurred (UnrecognizedClientException) when calling the Scan operation: The security token included in the request is invalid.
2023-11-29 17:22:37
Traceback (most recent call last):
  File "/home/laluna/summer2023/rosa_emic.py", line 160, in <module>
    checker.check_and_update()
  File "/home/laluna/summer2023/rosa_emic.py", line 61, in check_and_update
    response = self.table.scan(
  File "/home/laluna/Desktop/py395e/lib/python3.9/site-packages/boto3/resources/factory.py", line 580, in do_action
    response = action(self, *args, **kwargs)
  File "/home/laluna/Desktop/py395e/lib/python3.9/site-packages/boto3/resources/action.py", line 88, in __call__
    response = getattr(parent.meta.client, operation_name)(*args, **params)
  File "/home/laluna/Desktop/py395e/lib/python3.9/site-packages/botocore/client.py", line 535, in _api_call
    return self._make_api_call(operation_name, kwargs)
  File "/home/laluna/Desktop/py395e/lib/python3.9/site-packages/botocore/client.py", line 980, in _make_api_call
    raise error_class(parsed_response, operation_name)
botocore.exceptions.ClientError: An error occurred (UnrecognizedClientException) when calling the Scan operation: The security token included in the request is invalid.
2023-11-29 17:23:17
Traceback (most recent call last):
  File "/home/laluna/summer2023/rosa_emic.py", line 160, in <module>
    checker.check_and_update()
  File "/home/laluna/summer2023/rosa_emic.py", line 61, in check_and_update
    response = self.table.scan(
  File "/home/laluna/Desktop/py395e/lib/python3.9/site-packages/boto3/resources/factory.py", line 580, in do_action
    response = action(self, *args, **kwargs)
  File "/home/laluna/Desktop/py395e/lib/python3.9/site-packages/boto3/resources/action.py", line 88, in __call__
    response = getattr(parent.meta.client, operation_name)(*args, **params)
  File "/home/laluna/Desktop/py395e/lib/python3.9/site-packages/botocore/client.py", line 535, in _api_call
    return self._make_api_call(operation_name, kwargs)
  File "/home/laluna/Desktop/py395e/lib/python3.9/site-packages/botocore/client.py", line 980, in _make_api_call
    raise error_class(parsed_response, operation_name)
botocore.exceptions.ClientError: An error occurred (UnrecognizedClientException) when calling the Scan operation: The security token included in the request is invalid.
2023-11-29 17:25:37
Traceback (most recent call last):
  File "/home/laluna/summer2023/rosa_emic.py", line 160, in <module>
    checker.check_and_update()
  File "/home/laluna/summer2023/rosa_emic.py", line 61, in check_and_update
    response = self.table.scan(
  File "/home/laluna/Desktop/py395e/lib/python3.9/site-packages/boto3/resources/factory.py", line 580, in do_action
    response = action(self, *args, **kwargs)
  File "/home/laluna/Desktop/py395e/lib/python3.9/site-packages/boto3/resources/action.py", line 88, in __call__
    response = getattr(parent.meta.client, operation_name)(*args, **params)
  File "/home/laluna/Desktop/py395e/lib/python3.9/site-packages/botocore/client.py", line 535, in _api_call
    return self._make_api_call(operation_name, kwargs)
  File "/home/laluna/Desktop/py395e/lib/python3.9/site-packages/botocore/client.py", line 980, in _make_api_call
    raise error_class(parsed_response, operation_name)
botocore.exceptions.ClientError: An error occurred (UnrecognizedClientException) when calling the Scan operation: The security token included in the request is invalid.
2023-11-29 17:26:37
Traceback (most recent call last):
  File "/home/laluna/summer2023/rosa_emic.py", line 160, in <module>
    checker.check_and_update()
  File "/home/laluna/summer2023/rosa_emic.py", line 61, in check_and_update
    response = self.table.scan(
  File "/home/laluna/Desktop/py395e/lib/python3.9/site-packages/boto3/resources/factory.py", line 580, in do_action
    response = action(self, *args, **kwargs)
  File "/home/laluna/Desktop/py395e/lib/python3.9/site-packages/boto3/resources/action.py", line 88, in __call__
    response = getattr(parent.meta.client, operation_name)(*args, **params)
  File "/home/laluna/Desktop/py395e/lib/python3.9/site-packages/botocore/client.py", line 535, in _api_call
    return self._make_api_call(operation_name, kwargs)
  File "/home/laluna/Desktop/py395e/lib/python3.9/site-packages/botocore/client.py", line 980, in _make_api_call
    raise error_class(parsed_response, operation_name)
botocore.exceptions.ClientError: An error occurred (UnrecognizedClientException) when calling the Scan operation: The security token included in the request is invalid.
2023-11-29 17:27:37
Traceback (most recent call last):
  File "/home/laluna/summer2023/rosa_emic.py", line 160, in <module>
    checker.check_and_update()
  File "/home/laluna/summer2023/rosa_emic.py", line 61, in check_and_update
    response = self.table.scan(
  File "/home/laluna/Desktop/py395e/lib/python3.9/site-packages/boto3/resources/factory.py", line 580, in do_action
    response = action(self, *args, **kwargs)
  File "/home/laluna/Desktop/py395e/lib/python3.9/site-packages/boto3/resources/action.py", line 88, in __call__
    response = getattr(parent.meta.client, operation_name)(*args, **params)
  File "/home/laluna/Desktop/py395e/lib/python3.9/site-packages/botocore/client.py", line 535, in _api_call
    return self._make_api_call(operation_name, kwargs)
  File "/home/laluna/Desktop/py395e/lib/python3.9/site-packages/botocore/client.py", line 980, in _make_api_call
    raise error_class(parsed_response, operation_name)
botocore.exceptions.ClientError: An error occurred (UnrecognizedClientException) when calling the Scan operation: The security token included in the request is invalid.
2023-11-29 17:29:17
Traceback (most recent call last):
  File "/home/laluna/summer2023/rosa_emic.py", line 160, in <module>
    checker.check_and_update()
  File "/home/laluna/summer2023/rosa_emic.py", line 61, in check_and_update
    response = self.table.scan(
  File "/home/laluna/Desktop/py395e/lib/python3.9/site-packages/boto3/resources/factory.py", line 580, in do_action
    response = action(self, *args, **kwargs)
  File "/home/laluna/Desktop/py395e/lib/python3.9/site-packages/boto3/resources/action.py", line 88, in __call__
    response = getattr(parent.meta.client, operation_name)(*args, **params)
  File "/home/laluna/Desktop/py395e/lib/python3.9/site-packages/botocore/client.py", line 535, in _api_call
    return self._make_api_call(operation_name, kwargs)
  File "/home/laluna/Desktop/py395e/lib/python3.9/site-packages/botocore/client.py", line 980, in _make_api_call
    raise error_class(parsed_response, operation_name)
botocore.exceptions.ClientError: An error occurred (UnrecognizedClientException) when calling the Scan operation: The security token included in the request is invalid.
2023-11-29 17:31:17
Traceback (most recent call last):
  File "/home/laluna/summer2023/rosa_emic.py", line 160, in <module>
    checker.check_and_update()
  File "/home/laluna/summer2023/rosa_emic.py", line 61, in check_and_update
    response = self.table.scan(
  File "/home/laluna/Desktop/py395e/lib/python3.9/site-packages/boto3/resources/factory.py", line 580, in do_action
    response = action(self, *args, **kwargs)
  File "/home/laluna/Desktop/py395e/lib/python3.9/site-packages/boto3/resources/action.py", line 88, in __call__
    response = getattr(parent.meta.client, operation_name)(*args, **params)
  File "/home/laluna/Desktop/py395e/lib/python3.9/site-packages/botocore/client.py", line 535, in _api_call
    return self._make_api_call(operation_name, kwargs)
  File "/home/laluna/Desktop/py395e/lib/python3.9/site-packages/botocore/client.py", line 980, in _make_api_call
    raise error_class(parsed_response, operation_name)
botocore.exceptions.ClientError: An error occurred (UnrecognizedClientException) when calling the Scan operation: The security token included in the request is invalid.
2023-11-29 17:32:57
Traceback (most recent call last):
  File "/home/laluna/summer2023/rosa_emic.py", line 160, in <module>
    checker.check_and_update()
  File "/home/laluna/summer2023/rosa_emic.py", line 61, in check_and_update
    response = self.table.scan(
  File "/home/laluna/Desktop/py395e/lib/python3.9/site-packages/boto3/resources/factory.py", line 580, in do_action
    response = action(self, *args, **kwargs)
  File "/home/laluna/Desktop/py395e/lib/python3.9/site-packages/boto3/resources/action.py", line 88, in __call__
    response = getattr(parent.meta.client, operation_name)(*args, **params)
  File "/home/laluna/Desktop/py395e/lib/python3.9/site-packages/botocore/client.py", line 535, in _api_call
    return self._make_api_call(operation_name, kwargs)
  File "/home/laluna/Desktop/py395e/lib/python3.9/site-packages/botocore/client.py", line 980, in _make_api_call
    raise error_class(parsed_response, operation_name)
botocore.exceptions.ClientError: An error occurred (UnrecognizedClientException) when calling the Scan operation: The security token included in the request is invalid.
2023-11-29 17:34:16
Traceback (most recent call last):
  File "/home/laluna/summer2023/rosa_emic.py", line 160, in <module>
    checker.check_and_update()
  File "/home/laluna/summer2023/rosa_emic.py", line 61, in check_and_update
    response = self.table.scan(
  File "/home/laluna/Desktop/py395e/lib/python3.9/site-packages/boto3/resources/factory.py", line 580, in do_action
    response = action(self, *args, **kwargs)
  File "/home/laluna/Desktop/py395e/lib/python3.9/site-packages/boto3/resources/action.py", line 88, in __call__
    response = getattr(parent.meta.client, operation_name)(*args, **params)
  File "/home/laluna/Desktop/py395e/lib/python3.9/site-packages/botocore/client.py", line 535, in _api_call
    return self._make_api_call(operation_name, kwargs)
  File "/home/laluna/Desktop/py395e/lib/python3.9/site-packages/botocore/client.py", line 980, in _make_api_call
    raise error_class(parsed_response, operation_name)
botocore.exceptions.ClientError: An error occurred (UnrecognizedClientException) when calling the Scan operation: The security token included in the request is invalid.
2023-11-29 17:37:57
Traceback (most recent call last):
  File "/home/laluna/summer2023/rosa_emic.py", line 160, in <module>
    checker.check_and_update()
  File "/home/laluna/summer2023/rosa_emic.py", line 61, in check_and_update
    response = self.table.scan(
  File "/home/laluna/Desktop/py395e/lib/python3.9/site-packages/boto3/resources/factory.py", line 580, in do_action
    response = action(self, *args, **kwargs)
  File "/home/laluna/Desktop/py395e/lib/python3.9/site-packages/boto3/resources/action.py", line 88, in __call__
    response = getattr(parent.meta.client, operation_name)(*args, **params)
  File "/home/laluna/Desktop/py395e/lib/python3.9/site-packages/botocore/client.py", line 535, in _api_call
    return self._make_api_call(operation_name, kwargs)
  File "/home/laluna/Desktop/py395e/lib/python3.9/site-packages/botocore/client.py", line 980, in _make_api_call
    raise error_class(parsed_response, operation_name)
botocore.exceptions.ClientError: An error occurred (UnrecognizedClientException) when calling the Scan operation: The security token included in the request is invalid.
2023-11-29 17:38:17
Traceback (most recent call last):
  File "/home/laluna/summer2023/rosa_emic.py", line 160, in <module>
    checker.check_and_update()
  File "/home/laluna/summer2023/rosa_emic.py", line 61, in check_and_update
    response = self.table.scan(
  File "/home/laluna/Desktop/py395e/lib/python3.9/site-packages/boto3/resources/factory.py", line 580, in do_action
    response = action(self, *args, **kwargs)
  File "/home/laluna/Desktop/py395e/lib/python3.9/site-packages/boto3/resources/action.py", line 88, in __call__
    response = getattr(parent.meta.client, operation_name)(*args, **params)
  File "/home/laluna/Desktop/py395e/lib/python3.9/site-packages/botocore/client.py", line 535, in _api_call
    return self._make_api_call(operation_name, kwargs)
  File "/home/laluna/Desktop/py395e/lib/python3.9/site-packages/botocore/client.py", line 980, in _make_api_call
    raise error_class(parsed_response, operation_name)
botocore.exceptions.ClientError: An error occurred (UnrecognizedClientException) when calling the Scan operation: The security token included in the request is invalid.
2023-11-29 17:39:57
Traceback (most recent call last):
  File "/home/laluna/summer2023/rosa_emic.py", line 160, in <module>
    checker.check_and_update()
  File "/home/laluna/summer2023/rosa_emic.py", line 61, in check_and_update
    response = self.table.scan(
  File "/home/laluna/Desktop/py395e/lib/python3.9/site-packages/boto3/resources/factory.py", line 580, in do_action
    response = action(self, *args, **kwargs)
  File "/home/laluna/Desktop/py395e/lib/python3.9/site-packages/boto3/resources/action.py", line 88, in __call__
    response = getattr(parent.meta.client, operation_name)(*args, **params)
  File "/home/laluna/Desktop/py395e/lib/python3.9/site-packages/botocore/client.py", line 535, in _api_call
    return self._make_api_call(operation_name, kwargs)
  File "/home/laluna/Desktop/py395e/lib/python3.9/site-packages/botocore/client.py", line 980, in _make_api_call
    raise error_class(parsed_response, operation_name)
botocore.exceptions.ClientError: An error occurred (UnrecognizedClientException) when calling the Scan operation: The security token included in the request is invalid.
2023-11-29 17:40:37
Traceback (most recent call last):
  File "/home/laluna/summer2023/rosa_emic.py", line 160, in <module>
    checker.check_and_update()
  File "/home/laluna/summer2023/rosa_emic.py", line 61, in check_and_update
    response = self.table.scan(
  File "/home/laluna/Desktop/py395e/lib/python3.9/site-packages/boto3/resources/factory.py", line 580, in do_action
    response = action(self, *args, **kwargs)
  File "/home/laluna/Desktop/py395e/lib/python3.9/site-packages/boto3/resources/action.py", line 88, in __call__
    response = getattr(parent.meta.client, operation_name)(*args, **params)
  File "/home/laluna/Desktop/py395e/lib/python3.9/site-packages/botocore/client.py", line 535, in _api_call
    return self._make_api_call(operation_name, kwargs)
  File "/home/laluna/Desktop/py395e/lib/python3.9/site-packages/botocore/client.py", line 980, in _make_api_call
    raise error_class(parsed_response, operation_name)
botocore.exceptions.ClientError: An error occurred (UnrecognizedClientException) when calling the Scan operation: The security token included in the request is invalid.
